Workbook

Sheet Summary
A1: Test summary by system
A3: System | B3: Total | C3: Automated | D3: Manual | E3: Pass | F3: Fail | G3: Blocked | H3: Not run | I3: % passed
A4: SmartPRS2 | B4: =COUNTIF('Test Cases'!$B$5:$B$45,A4) -> 17 | C4: =COUNTIFS('Test Cases'!$B$5:$B$45,A4,'Test Cases'!$I$5:$I$45,"Auto") -> 11 | D4: =COUNTIFS('Test Cases'!$B$5:$B$45,A4,'Test Cases'!$I$5:$I$45,"Manual") -> 6 | E4: =COUNTIFS('Test Cases'!$B$5:$B$45,A4,'Test Cases'!$K$5:$K$45,"Pass") -> 11 | F4: =COUNTIFS('Test Cases'!$B$5:$B$45,A4,'Test Cases'!$K$5:$K$45,"Fail") -> 0 | G4: =COUNTIFS('Test Cases'!$B$5:$B$45,A4,'Test Cases'!$K$5:$K$45,"Blocked") -> 0 | H4: =COUNTIFS('Test Cases'!$B$5:$B$45,A4,'Test Cases'!$K$5:$K$45,"Not run") -> 6 | I4: =IF(B4=0,0,E4/B4) -> 0.64705882
A5: SmartEPT | B5: =COUNTIF('Test Cases'!$B$5:$B$45,A5) -> 9 | C5: =COUNTIFS('Test Cases'!$B$5:$B$45,A5,'Test Cases'!$I$5:$I$45,"Auto") -> 6 | D5: =COUNTIFS('Test Cases'!$B$5:$B$45,A5,'Test Cases'!$I$5:$I$45,"Manual") -> 3 | E5: =COUNTIFS('Test Cases'!$B$5:$B$45,A5,'Test Cases'!$K$5:$K$45,"Pass") -> 6 | F5: =COUNTIFS('Test Cases'!$B$5:$B$45,A5,'Test Cases'!$K$5:$K$45,"Fail") -> 0 | G5: =COUNTIFS('Test Cases'!$B$5:$B$45,A5,'Test Cases'!$K$5:$K$45,"Blocked") -> 0 | H5: =COUNTIFS('Test Cases'!$B$5:$B$45,A5,'Test Cases'!$K$5:$K$45,"Not run") -> 3 | I5: =IF(B5=0,0,E5/B5) -> 0.66666667
A6: Caller | B6: =COUNTIF('Test Cases'!$B$5:$B$45,A6) -> 9 | C6: =COUNTIFS('Test Cases'!$B$5:$B$45,A6,'Test Cases'!$I$5:$I$45,"Auto") -> 3 | D6: =COUNTIFS('Test Cases'!$B$5:$B$45,A6,'Test Cases'!$I$5:$I$45,"Manual") -> 6 | E6: =COUNTIFS('Test Cases'!$B$5:$B$45,A6,'Test Cases'!$K$5:$K$45,"Pass") -> 3 | F6: =COUNTIFS('Test Cases'!$B$5:$B$45,A6,'Test Cases'!$K$5:$K$45,"Fail") -> 0 | G6: =COUNTIFS('Test Cases'!$B$5:$B$45,A6,'Test Cases'!$K$5:$K$45,"Blocked") -> 0 | H6: =COUNTIFS('Test Cases'!$B$5:$B$45,A6,'Test Cases'!$K$5:$K$45,"Not run") -> 6 | I6: =IF(B6=0,0,E6/B6) -> 0.33333333
A7: Android app | B7: =COUNTIF('Test Cases'!$B$5:$B$45,A7) -> 4 | C7: =COUNTIFS('Test Cases'!$B$5:$B$45,A7,'Test Cases'!$I$5:$I$45,"Auto") -> 0 | D7: =COUNTIFS('Test Cases'!$B$5:$B$45,A7,'Test Cases'!$I$5:$I$45,"Manual") -> 4 | E7: =COUNTIFS('Test Cases'!$B$5:$B$45,A7,'Test Cases'!$K$5:$K$45,"Pass") -> 0 | F7: =COUNTIFS('Test Cases'!$B$5:$B$45,A7,'Test Cases'!$K$5:$K$45,"Fail") -> 0 | G7: =COUNTIFS('Test Cases'!$B$5:$B$45,A7,'Test Cases'!$K$5:$K$45,"Blocked") -> 0 | H7: =COUNTIFS('Test Cases'!$B$5:$B$45,A7,'Test Cases'!$K$5:$K$45,"Not run") -> 4 | I7: =IF(B7=0,0,E7/B7) -> 0
A8: End to end | B8: =COUNTIF('Test Cases'!$B$5:$B$45,A8) -> 2 | C8: =COUNTIFS('Test Cases'!$B$5:$B$45,A8,'Test Cases'!$I$5:$I$45,"Auto") -> 0 | D8: =COUNTIFS('Test Cases'!$B$5:$B$45,A8,'Test Cases'!$I$5:$I$45,"Manual") -> 2 | E8: =COUNTIFS('Test Cases'!$B$5:$B$45,A8,'Test Cases'!$K$5:$K$45,"Pass") -> 0 | F8: =COUNTIFS('Test Cases'!$B$5:$B$45,A8,'Test Cases'!$K$5:$K$45,"Fail") -> 0 | G8: =COUNTIFS('Test Cases'!$B$5:$B$45,A8,'Test Cases'!$K$5:$K$45,"Blocked") -> 0 | H8: =COUNTIFS('Test Cases'!$B$5:$B$45,A8,'Test Cases'!$K$5:$K$45,"Not run") -> 2 | I8: =IF(B8=0,0,E8/B8) -> 0
A9: Total | B9: =SUM(B4:B8) -> 41 | C9: =SUM(C4:C8) -> 20 | D9: =SUM(D4:D8) -> 21 | E9: =SUM(E4:E8) -> 20 | F9: =SUM(F4:F8) -> 0 | G9: =SUM(G4:G8) -> 0 | H9: =SUM(H4:H8) -> 21 | I9: =IF(B9=0,0,E9/B9) -> 0.48780488
A11: Counts update automatically from the Status column on the Test Cases sheet.

Sheet Test Cases
A1: Caller ⇄ SmartPRS2 ⇄ SmartEPT — Field-force integration test cases (6 Oct 2026)
A2: Fill in: Status (dropdown), Tested by, Test date, Remarks (yellow columns). 'Auto' rows were run in a clean test environment on 6 Oct 2026 and passed; re-run them with php artisan test / composer test.
A4: Test ID | B4: System | C4: Area | D4: Scenario | E4: Preconditions | F4: Steps | G4: Test data | H4: Expected result | I4: Type | J4: Automated test | K4: Status | L4: Tested by | M4: Test date | N4: Remarks
A5: PRS-01 | B5: SmartPRS2 | C5: Geofence check | D5: Employee inside fence can sign in | E5: Employee FF01 has strict 0.5 km fence at office 17.4600, 78.3600; API key with scope ingest | F5: POST /api/v1/fieldforce/geofence/check | G5: emp_code=ff01, lat=17.4610, lng=78.3605 | H5: 200; allowed=true; status=within | I5: Auto | J5: CallerFieldForceTest: allows sign-in inside the fence | K5: Pass | L5: Claude (automated) | M5: 46301
A6: PRS-02 | B6: SmartPRS2 | C6: Geofence check | D6: Employee outside fence is blocked | E6: Same as PRS-01 | F6: POST geofence/check | G6: lat=17.3850, lng=78.4867 (~13 km away) | H6: 200; allowed=false; status=outside; message shows distance and limit | I6: Auto | J6: CallerFieldForceTest: …blocks it outside | K6: Pass | L6: Claude (automated) | M6: 46301
A7: PRS-03 | B7: SmartPRS2 | C7: Geofence check | D7: No GPS with strict fence | E7: Same as PRS-01 | F7: POST geofence/check without lat/lng | G7: emp_code=FF01 | H7: allowed=false; status=no-gps; message asks to turn on location | I7: Auto | J7: CallerFieldForceTest: …blocks it outside | K7: Pass | L7: Claude (automated) | M7: 46301
A8: PRS-04 | B8: SmartPRS2 | C8: Geofence check | D8: No GPS with 1 km / 2 km fence | E8: Fence Outside = 1km | F8: POST geofence/check without lat/lng | G8: emp_code with 1km fence | H8: allowed=true; status=no-gps | I8: Manual | K8: Not run
A9: PRS-05 | B9: SmartPRS2 | C9: Geofence check | D9: Employee with no fence rule | E9: Employee FF02, no geofence_rules row | F9: POST geofence/check | G9: emp_code=FF02, lat=1, lng=1 | H9: allowed=true; status=no-rule | I9: Auto | J9: CallerFieldForceTest: lets employees without a fence… | K9: Pass | L9: Claude (automated) | M9: 46301
A10: PRS-06 | B10: SmartPRS2 | C10: Geofence check | D10: Code unknown to PRS | E10: — | F10: POST geofence/check | G10: emp_code=NOPE | H10: allowed=true; employee_found=false | I10: Auto | J10: CallerFieldForceTest: lets employees without a fence… | K10: Pass | L10: Claude (automated) | M10: 46301
A11: PRS-07 | B11: SmartPRS2 | C11: Geofence check | D11: Grace distance applied (1 km mode) | E11: Fence 0.5 km, Outside=1km | F11: POST geofence/check at ~1.2 km | G11: point 1.2 km from start | H11: allowed=true (limit 1.5 km); status=within | I11: Manual | K11: Not run
A12: PRS-08 | B12: SmartPRS2 | C12: Security | D12: Call without API key | E12: — | F12: POST geofence/check, no X-Api-Key | G12: emp_code=X | H12: 401 API_KEY_401 | I12: Auto | J12: CallerFieldForceTest: refuses calls without a key | K12: Pass | L12: Claude (automated) | M12: 46301
A13: PRS-09 | B13: SmartPRS2 | C13: Security | D13: Key from another workspace cannot see employee | E13: Key bound to tenant B; employee in tenant A | F13: POST geofence/check | G13: emp_code of tenant A | H13: employee_found=false (no cross-tenant leak) | I13: Manual | K13: Not run
A14: PRS-10 | B14: SmartPRS2 | C14: Attendance | D14: Login stored as IN in local time | E14: App timezone Asia/Kolkata | F14: POST /api/v1/fieldforce/attendance | G14: type=login, at=2026-10-06T04:00:00Z | H14: accepted; attendance_logs row direction=in, source=caller, punch_at 09:30:00 | I14: Auto | J14: CallerFieldForceTest: stores login/logout… | K14: Pass | L14: Claude (automated) | M14: 46301
A15: PRS-11 | B15: SmartPRS2 | C15: Attendance | D15: Logout stored as OUT with geo verdict | E15: Fence set | F15: POST attendance | G15: type=logout, far location | H15: accepted; direction=out; geo_status=outside | I15: Auto | J15: CallerFieldForceTest: stores login/logout… | K15: Pass | L15: Claude (automated) | M15: 46301
A16: PRS-12 | B16: SmartPRS2 | C16: Attendance | D16: Time without offset rejected | E16: — | F16: POST attendance | G16: at=2026-10-06 09:30:00 | H16: status=rejected (VALIDATION); no row | I16: Auto | J16: CallerFieldForceTest: stores login/logout… | K16: Pass | L16: Claude (automated) | M16: 46301
A17: PRS-13 | B17: SmartPRS2 | C17: Attendance | D17: Unknown employee code | E17: — | F17: POST attendance | G17: emp_code=GHOST | H17: status=unknown_employee; no row | I17: Auto | J17: CallerFieldForceTest: stores login/logout… | K17: Pass | L17: Claude (automated) | M17: 46301
A18: PRS-14 | B18: SmartPRS2 | C18: Attendance | D18: Retry is not duplicated | E18: Event c-1 already accepted | F18: POST same event again | G18: external_id=c-1 | H18: status=duplicate; still one row | I18: Auto | J18: CallerFieldForceTest: stores login/logout… | K18: Pass | L18: Claude (automated) | M18: 46301
A19: PRS-15 | B19: SmartPRS2 | C19: Attendance | D19: Caller punch appears in Attendance Report | E19: Login + logout accepted for today | F19: Open Attendance Report for the employee | G19: — | H19: First In / Last Out show app login/logout times | I19: Manual | K19: Not run
A20: PRS-16 | B20: SmartPRS2 | C20: Attendance | D20: Late-arrival mail triggered | E20: Late policy active; login after grace | F20: Send login event after shift start + grace | G20: — | H20: Late-arrival notification queued as for biometric punch | I20: Manual | K20: Not run
A21: PRS-17 | B21: SmartPRS2 | C21: Migration | D21: Geo columns migration is safe to rerun | E21: Live DB already has lat/lng from self punch | F21: php artisan migrate | G21: — | H21: Migrates without error; existing data untouched | I21: Manual | K21: Not run
A22: EPT-01 | B22: SmartEPT | C22: Punch API | D22: Sign-in punch keeps location | E22: API key ingest+read; employee E-1001 | F22: POST /api/v1/attendance/punches | G22: punch_type=IN, source=CALLER, lat/lng, geo_status=within | H22: 202; biometric_logs.metadata has lat, lng, geo_status, source=CALLER | I22: Auto | J22: CallerFieldForceTest: test_sign_in_punch_keeps_location_in_metadata | K22: Pass | L22: Claude (automated) | M22: 46301
A23: EPT-02 | B23: SmartEPT | C23: Punch API | D23: Existing biometric bridge unaffected | E23: — | F23: Run existing SBB punch tests | G23: — | H23: All 18 SbbPunchIngestTest tests pass | I23: Auto | J23: SbbPunchIngestTest (existing) | K23: Pass | L23: Claude (automated) | M23: 46301
A24: EPT-03 | B24: SmartEPT | C24: Punch API | D24: Caller IN creates attendance + gate | E24: Gate-to-PC enabled for company | F24: Sign in on app, then log in on PC | G24: — | H24: EPT attendance shows check-in; PC login allowed by gate | I24: Manual | K24: Not run
A25: EPT-04 | B25: SmartEPT | C25: Field trail | D25: Exit raises one violation | E25: Employee E-1001 | F25: POST /api/v1/fieldforce/locations: within, outside, outside | G25: 3 fixes 5 min apart | H25: stored=3; exactly one GEOFENCE_EXIT, unresolved | I25: Auto | J25: CallerFieldForceTest: test_leaving_the_fence_raises_one_violation… | K25: Pass | L25: Claude (automated) | M25: 46301
A26: EPT-05 | B26: SmartEPT | C26: Field trail | D26: Return resolves violation | E26: After EPT-04 | F26: POST a within fix | G26: — | H26: GEOFENCE_EXIT resolved_at set | I26: Auto | J26: CallerFieldForceTest: test_leaving_the_fence… | K26: Pass | L26: Claude (automated) | M26: 46301
A27: EPT-06 | B27: SmartEPT | C27: Field trail | D27: Re-delivered fix ignored | E27: After EPT-04 | F27: POST same external_id again | G27: — | H27: stored=0; no new violation | I27: Auto | J27: CallerFieldForceTest: test_leaving_the_fence… | K27: Pass | L27: Claude (automated) | M27: 46301
A28: EPT-07 | B28: SmartEPT | C28: Field trail | D28: Read a day's trail | E28: Fixes stored | F28: GET /api/v1/fieldforce/locations?employee_code=e-1001 | G28: — | H28: count = fixes stored (case-insensitive code) | I28: Auto | J28: CallerFieldForceTest: test_leaving_the_fence… | K28: Pass | L28: Claude (automated) | M28: 46301
A29: EPT-08 | B29: SmartEPT | C29: Violations | D29: GEOFENCE_EXIT visible in dashboard | E29: After EPT-04 | F29: Open Violations feed in EPT admin | G29: — | H29: Event shown: DEVICE / MEDIUM / distance and limit | I29: Manual | K29: Not run
A30: EPT-09 | B30: SmartEPT | C30: Migration | D30: field_force_locations created | E30: — | F30: php artisan migrate | G30: — | H30: Table created; no other table changed | I30: Manual | K30: Not run
A31: CAL-01 | B31: Caller | C31: Sign-in | D31: Outside fence blocked, nothing recorded | E31: PRS + EPT connected; Block sign-in on | F31: Sign in with far GPS | G31: — | H31: 422 outside_geofence with PRS message; no work session; outbox empty | I31: Auto | J31: FieldForceIntegrationTest: test_sign_in_outside… | K31: Pass | L31: Claude (automated) | M31: 46301
A32: CAL-02 | B32: Caller | C32: Sign-in | D32: Inside fence: attendance, punch and trail sent | E32: Same | F32: Sign in inside, send far GPS fix, sign out | G32: — | H32: Outbox: PRS login, EPT IN, EPT location (outside), PRS logout, EPT OUT; all delivered | I32: Auto | J32: FieldForceIntegrationTest: test_sign_in_inside… | K32: Pass | L32: Claude (automated) | M32: 46301
A33: CAL-03 | B33: Caller | C33: Sign-in | D33: PRS down does not lock staff out | E33: PRS returns 503 | F33: Sign in | G33: — | H33: Sign-in allowed (unverified); PRS event retried later; EPT delivered | I33: Auto | J33: FieldForceIntegrationTest: test_prs_outage… | K33: Pass | L33: Claude (automated) | M33: 46301
A34: CAL-04 | B34: Caller | C34: Sign-in | D34: Record-only mode | E34: Untick Block sign-in outside geofence | F34: Sign in outside | G34: — | H34: Sign-in allowed; attendance geo_status=outside in PRS | I34: Manual | K34: Not run
A35: CAL-05 | B35: Caller | C35: Sign-in | D35: No integration configured | E35: No connections saved | F35: Sign in | G35: — | H35: Works exactly as before; no outbox rows | I35: Manual | K35: Not run
A36: CAL-06 | B36: Caller | C36: Admin | D36: Integrations page loads (MySQL 8) | E36: Admin console rebuilt | F36: Open Administration → Integrations | G36: — | H36: Two cards, no SQL error | I36: Manual | K36: Not run
A37: CAL-07 | B37: Caller | C37: Admin | D37: Save & test with valid key | E37: PRS key with ingest | F37: Enter URL + key, Save & test | G37: — | H37: Connected to <company name> | I37: Manual | K37: Not run
A38: CAL-08 | B38: Caller | C38: Admin | D38: Save & test with wrong key | E38: — | F38: Enter wrong key | G38: — | H38: Could not connect: 401 API key is not valid | I38: Manual | K38: Not run
A39: CAL-09 | B39: Caller | C39: Admin | D39: Send waiting data now | E39: Outbox has pending/failed rows | F39: Click Send waiting data now | G39: — | H39: Rows delivered; counts update | I39: Manual | K39: Not run
A40: APP-01 | B40: Android app | C40: Field test | D40: Real sign-in inside office | E40: OPPO phone, location on, fence set in PRS | F40: Sign in at office | G40: — | H40: Signed in; PRS shows IN with lat/lng within | I40: Manual | K40: Not run
A41: APP-02 | B41: Android app | C41: Field test | D41: Real sign-in away from office | E41: Same | F41: Sign in > radius away | G41: — | H41: Refused with distance message | I41: Manual | K41: Not run
...
